Workbook

Sheet DZIENNY TRACKER
A1: DZIENNY TRACKER — CZY DZIŚ ZARABIAMY?
A3: KOSZTY STAŁE MIESIĘCZNE | D3: SPRZEDAŻ DZIENNA — WPISUJ CODZIENNIE
A4: Wynagrodzenia (Sp. z o.o.) | B4: 87539 | D4: Dzień | E4: Sprzedaż | F4: Zysk brutto | G4: Minus koszty | H4: Narastająco
A5: Wynagrodzenia (JDG umowy) | B5: 22675 | D5: 1 | F5: =IF(E5="","",ROUND(E5*$B$27,0)) | G5: =IF(E5="","",F5-$B$25) | H5: =IF(E5="","",G5)
A6: Magazyn (najem) | B6: 10000 | D6: 2 | F6: =IF(E6="","",ROUND(E6*$B$27,0)) | G6: =IF(E6="","",F6-$B$25) | H6: =IF(E6="","",IF(H5="",G6,H5+G6))
A7: Księgowość | B7: 5845 | D7: 3 | F7: =IF(E7="","",ROUND(E7*$B$27,0)) | G7: =IF(E7="","",F7-$B$25) | H7: =IF(E7="","",IF(H6="",G7,H6+G7))
A8: Media (prąd, woda, śmieci) | B8: 1301 | D8: 4 | F8: =IF(E8="","",ROUND(E8*$B$27,0)) | G8: =IF(E8="","",F8-$B$25) | H8: =IF(E8="","",IF(H7="",G8,H7+G8))
A9: Paliwo | B9: 5000 | D9: 5 | F9: =IF(E9="","",ROUND(E9*$B$27,0)) | G9: =IF(E9="","",F9-$B$25) | H9: =IF(E9="","",IF(H8="",G9,H8+G9))
A10: Leasing Opel Movano | B10: 2475 | D10: 6 | F10: =IF(E10="","",ROUND(E10*$B$27,0)) | G10: =IF(E10="","",F10-$B$25) | H10: =IF(E10="","",IF(H9="",G10,H9+G10))
A11: Leasing Ford Custom | B11: 1687 | D11: 7 | F11: =IF(E11="","",ROUND(E11*$B$27,0)) | G11: =IF(E11="","",F11-$B$25) | H11: =IF(E11="","",IF(H10="",G11,H10+G11))
A12: Leasing 2x BMW | B12: 3298 | D12: 8 | F12: =IF(E12="","",ROUND(E12*$B$27,0)) | G12: =IF(E12="","",F12-$B$25) | H12: =IF(E12="","",IF(H11="",G12,H11+G12))
A13: Dzierżawa aut z JDG | B13: 3900 | D13: 9 | F13: =IF(E13="","",ROUND(E13*$B$27,0)) | G13: =IF(E13="","",F13-$B$25) | H13: =IF(E13="","",IF(H12="",G13,H12+G13))
A14: GPS (Widziszwszystko) | B14: 300 | D14: 10 | F14: =IF(E14="","",ROUND(E14*$B$27,0)) | G14: =IF(E14="","",F14-$B$25) | H14: =IF(E14="","",IF(H13="",G14,H13+G14))
A15: Zarządzanie operacyjne JDG | B15: 5000 | D15: 11 | F15: =IF(E15="","",ROUND(E15*$B$27,0)) | G15: =IF(E15="","",F15-$B$25) | H15: =IF(E15="","",IF(H14="",G15,H14+G15))
A16: Marketing | B16: 470 | D16: 12 | F16: =IF(E16="","",ROUND(E16*$B$27,0)) | G16: =IF(E16="","",F16-$B$25) | H16: =IF(E16="","",IF(H15="",G16,H15+G16))
A17: Finansowanie/raty | B17: 1824 | D17: 13 | F17: =IF(E17="","",ROUND(E17*$B$27,0)) | G17: =IF(E17="","",F17-$B$25) | H17: =IF(E17="","",IF(H16="",G17,H16+G17))
... A21: Inne stałe | B21: 700 | D21: 17 | F21: =IF(E21="","",ROUND(E21*$B$27,0)) | G21: =IF(E21="","",F21-$B$25) | H21: =IF(E21="","",IF(H20="",G21,H20+G21))
A22: SUMA KOSZTÓW STAŁYCH / MC | B22: =SUM(B4:B21) | D22: 18 | F22: =IF(E22="","",ROUND(E22*$B$27,0)) | G22: =IF(E22="","",F22-$B$25) | H22: =IF(E22="","",IF(H21="",G22,H21+G22))
D23: 19 | F23: =IF(E23="","",ROUND(E23*$B$27,0)) | G23: =IF(E23="","",F23-$B$25) | H23: =IF(E23="","",IF(H22="",G23,H22+G23))
A24: Dni robocze w miesiącu | B24: 21 | D24: 20 | F24: =IF(E24="","",ROUND(E24*$B$27,0)) | G24: =IF(E24="","",F24-$B$25) | H24: =IF(E24="","",IF(H23="",G24,H23+G24))
A25: KOSZT DZIENNY (stałe/dzień) | B25: =ROUND(B22/B24,0) | D25: 21 | F25: =IF(E25="","",ROUND(E25*$B$27,0)) | G25: =IF(E25="","",F25-$B$25) | H25: =IF(E25="","",IF(H24="",G25,H24+G25))
D26: 22 | F26: =IF(E26="","",ROUND(E26*$B$27,0)) | G26: =IF(E26="","",F26-$B$25) | H26: =IF(E26="","",IF(H25="",G26,H25+G26))
A27: Marża na sprzedaży | B27: 0.354 | D27: 23 | F27: =IF(E27="","",ROUND(E27*$B$27,0)) | G27: =IF(E27="","",F27-$B$25) | H27: =IF(E27="","",IF(H26="",G27,H26+G27))
A28: MIN. OBRÓT DZIENNY (break-even) | B28: =ROUND(B25/B27,0) | D28: 24 | F28: =IF(E28="","",ROUND(E28*$B$27,0)) | G28: =IF(E28="","",F28-$B$25) | H28: =IF(E28="","",IF(H27="",G28,H27+G28))
D29: 25 | F29: =IF(E29="","",ROUND(E29*$B$27,0)) | G29: =IF(E29="","",F29-$B$25) | H29: =IF(E29="","",IF(H28="",G29,H28+G29))
A30: ^ Tyle musisz sprzedać dziennie, żeby wyjść na ZERO | D30: 26 | F30: =IF(E30="","",ROUND(E30*$B$27,0)) | G30: =IF(E30="","",F30-$B$25) | H30: =IF(E30="","",IF(H29="",G30,H29+G30))
D31: 27 | F31: =IF(E31="","",ROUND(E31*$B$27,0)) | G31: =IF(E31="","",F31-$B$25) | H31: =IF(E31="","",IF(H30="",G31,H30+G31))
D32: 28 | F32: =IF(E32="","",ROUND(E32*$B$27,0)) | G32: =IF(E32="","",F32-$B$25) | H32: =IF(E32="","",IF(H31="",G32,H31+G32))
D33: 29 | F33: =IF(E33="","",ROUND(E33*$B$27,0)) | G33: =IF(E33="","",F33-$B$25) | H33: =IF(E33="","",IF(H32="",G33,H32+G33))
D34: 30 | F34: =IF(E34="","",ROUND(E34*$B$27,0)) | G34: =IF(E34="","",F34-$B$25) | H34: =IF(E34="","",IF(H33="",G34,H33+G34))
D35: 31 | F35: =IF(E35="","",ROUND(E35*$B$27,0)) | G35: =IF(E35="","",F35-$B$25) | H35: =IF(E35="","",IF(H34="",G35,H34+G35))
D36: SUMA | E36: =SUM(E5:E35) | F36: =SUM(F5:F35) | G36: =SUM(G5:G35) | H36: =H35
D38: PODSUMOWANIE MIESIĄCA
D39: Sprzedaż miesiąca | E39: =E36
D40: Zysk brutto (po marży) | E40: =F36
D41: Koszty stałe miesiąca | E41: =B22
D42: WYNIK MIESIĄCA | E42: =F36-B22
D43: Dni z wpisaną sprzedażą | E43: =COUNTA(E5:E35)
D44: Średnia sprzedaż/dzień | E44: =IF(COUNTA(E5:E35)=0,"",E36/COUNTA(E5:E35))
D47: LEGENDA:
...

Sheet PROGNOZA 2026
A1: BUDŻET 2026 — ADD ALL SP. Z O.O.
A2: Data utworzenia: | B2: 2026-02-08 | E2: Waluta: PLN
A4: PRZYCHODY
A5: Kategoria | B5: Sty | C5: Lut | D5: Mar | E5: Kwi | F5: Maj | G5: Cze | H5: Lip | I5: Sie | J5: Wrz | K5: Paź | L5: Lis | M5: Gru | N5: RAZEM ROK | O5: % PLANU
A6: Sprzedaż produktów | B6: 450000 | C6: 450000 | D6: 450000 | E6: 450000 | F6: 450000 | G6: 450000 | H6: 450000 | I6: 450000 | J6: 450000 | K6: 450000 | L6: 450000 | M6: 450000 | N6: =SUM(B6:M6)
A7: Przychody zewnętrzne | B7: 0 | C7: 0 | D7: 0 | E7: 0 | F7: 0 | G7: 0 | H7: 0 | I7: 0 | J7: 0 | K7: 0 | L7: 0 | M7: 0 | N7: =SUM(B7:M7)
A8: Przychody wewnętrzne | B8: 0 | C8: 0 | D8: 0 | E8: 0 | F8: 0 | G8: 0 | H8: 0 | I8: 0 | J8: 0 | K8: 0 | L8: 0 | M8: 0 | N8: =SUM(B8:M8)
A9: PRZYCHODY OGÓŁEM | B9: =SUM(B6:B8) | C9: =SUM(C6:C8) | D9: =SUM(D6:D8) | E9: =SUM(E6:E8) | F9: =SUM(F6:F8) | G9: =SUM(G6:G8) | H9: =SUM(H6:H8) | I9: =SUM(I6:I8) | ... M9: =SUM(M6:M8) | N9: =SUM(B9:M9)
A11: KOSZTY
A12: Kategoria | B12: Sty | C12: Lut | D12: Mar | E12: Kwi | F12: Maj | G12: Cze | H12: Lip | I12: Sie | J12: Wrz | K12: Paź | L12: Lis | M12: Gru | N12: RAZEM ROK | O12: % PRZYCH.
A13: Zakupy towarów | B13: 290700 | C13: 290700 | D13: 290700 | E13: 290700 | F13: 290700 | G13: 290700 | H13: 290700 | I13: 290700 | J13: 290700 | K13: 290700 | L13: 290700 | M13: 290700 | N13: =SUM(B13:M13) | O13: =IF(N9=0,"",N13/N9)
A14: Prowizje | B14: 4250 | C14: 4250 | D14: 4250 | E14: 4250 | F14: 4250 | G14: 4250 | H14: 4250 | I14: 4250 | J14: 4250 | K14: 4250 | L14: 4250 | M14: 4250 | N14: =SUM(B14:M14) | O14: =IF(N9=0,"",N14/N9)
A15: Wynagrodzenia | B15: ='WYNAGRODZENIA 2026'!F2 | C15: ='WYNAGRODZENIA 2026'!G2 | D15: ='WYNAGRODZENIA 2026'!H2 | E15: ='WYNAGRODZENIA 2026'!I2 | F15: ='WYNAGRODZENIA 2026'!J2 | G15: ='WYNAGRODZENIA 2026'!K2 | H15: ='WYNAGRODZENIA 2026'!L2 | I15: ='WYNAGRODZENIA 2026'!M2 | ... M15: ='WYNAGRODZENIA 2026'!Q2 | N15: =SUM(B15:M15) | O15: =IF(N9=0,"",N15/N9)
A16: Koszty operacyjne | B16: ='OPERACYJNE 2026'!F2 | C16: ='OPERACYJNE 2026'!G2 | D16: ='OPERACYJNE 2026'!H2 | E16: ='OPERACYJNE 2026'!I2 | F16: ='OPERACYJNE 2026'!J2 | G16: ='OPERACYJNE 2026'!K2 | H16: ='OPERACYJNE 2026'!L2 | I16: ='OPERACYJNE 2026'!M2 | ... M16: ='OPERACYJNE 2026'!Q2 | N16: =SUM(B16:M16) | O16: =IF(N9=0,"",N16/N9)
A17: Samochody / Amortyzacja | B17: ='SAMOCHODY 2026'!F2 | C17: ='SAMOCHODY 2026'!G2 | D17: ='SAMOCHODY 2026'!H2 | E17: ='SAMOCHODY 2026'!I2 | F17: ='SAMOCHODY 2026'!J2 | G17: ='SAMOCHODY 2026'!K2 | H17: ='SAMOCHODY 2026'!L2 | I17: ='SAMOCHODY 2026'!M2 | ... M17: ='SAMOCHODY 2026'!Q2 | N17: =SUM(B17:M17) | O17: =IF(N9=0,"",N17/N9)
A18: KOSZTY OGÓŁEM | B18: =SUM(B13:B17) | C18: =SUM(C13:C17) | D18: =SUM(D13:D17) | E18: =SUM(E13:E17) | F18: =SUM(F13:F17) | G18: =SUM(G13:G17) | H18: =SUM(H13:H17) | I18: =SUM(I13:I17) | ... M18: =SUM(M13:M17) | N18: =SUM(B18:M18) | O18: =IF(N9=0,"",N18/N9)
A20: WYNIK BRUTTO (Zysk/Strata) | B20: =B9-B18 | C20: =C9-C18 | D20: =D9-D18 | E20: =E9-E18 | F20: =F9-F18 | G20: =G9-G18 | H20: =H9-H18 | I20: =I9-I18 | ... M20: =M9-M18 | N20: =SUM(B20:M20)
A21: WYNIK NARASTAJĄCO | B21: =B20 | C21: =B21+C20 | D21: =C21+D20 | E21: =D21+E20 | F21: =E21+F20 | G21: =F21+G20 | H21: =G21+H20 | I21: =H21+I20 | J21: =I21+J20 | ... M21: =L21+M20
A22: RENTOWNOŚĆ MIESIĘCZNA | B22: =IF(B9=0,"",B20/B9) | C22: =IF(C9=0,"",C20/C9) | D22: =IF(D9=0,"",D20/D9) | E22: =IF(E9=0,"",E20/E9) | F22: =IF(F9=0,"",F20/F9) | G22: =IF(G9=0,"",G20/G9) | H22: =IF(H9=0,"",H20/H9) | I22: =IF(I9=0,"",I20/I9) | ... M22: =IF(M9=0,"",M20/M9)
A24: UMOWY Z ADDALL JDG
A25: Umowa | B25: Koszt netto | C25: Kategoria | D25: Płatność
A26: Umowa menadżerska - A. Rękawek | B26: 11850 | C26: Wynagrodzenia | D26: Przelew
A27: Umowa dysponowania pracownikami | B27: 22674.54 | C27: Wynagrodzenia | D27: Przelew
A28: Umowa zarządzania operacyjnego | B28: 5000 | C28: Operacyjny | D28: Gotówka
A29: Umowa dzierżawy | B29: 3900 | C29: Samochody | D29: Gotówka
A32: KOSZTY WYNAGRODZEŃ WG DZIAŁÓW (miesięcznie)
A33: Dział | B33: Sty | C33: Lut | D33: Mar | E33: Kwi | F33: Maj | G33: Cze | H33: Lip | I33: Sie | J33: Wrz | K33: Paź | L33: Lis | M33: Gru | N33: RAZEM
A34: SPRZEDAŻ | B34: 19720 | C34: 19720 | D34: 19720 | E34: 19720 | F34: 19720 | G34: 19720 | H34: 19720 | I34: 19720 | J34: 19720 | K34: 19720 | L34: 19720 | M34: 19720 | N34: =SUM(B34:M34)
A35: LOGISTYKA | B35: 37201.5 | C35: 37201.5 | D35: 37201.5 | E35: 37201.5 | F35: 37201.5 | G35: 37201.5 | H35: 37201.5 | I35: 37201.5 | J35: 37201.5 | K35: 37201.5 | L35: 37201.5 | M35: 37201.5 | N35: =SUM(B35:M35)
A36: OPERACJE | B36: 9572.05 | C36: 9572.05 | D36: 9572.05 | E36: 9572.05 | F36: 9572.05 | G36: 9572.05 | H36: 9572.05 | I36: 9572.05 | J36: 9572.05 | K36: 9572.05 | L36: 9572.05 | M36: 9572.05 | N36: =SUM(B36:M36)
A37: WSPARCIE | B37: 0 | C37: 0 | D37: 0 | E37: 0 | F37: 0 | G37: 0 | H37: 0 | I37: 0 | J37: 0 | K37: 0 | L37: 0 | M37: 0 | N37: =SUM(B37:M37)
A38: MAGAZYN | B38: 16923 | C38: 16923 | D38: 16923 | E38: 16923 | F38: 16923 | G38: 16923 | H38: 16923 | I38: 16923 | J38: 16923 | K38: 16923 | L38: 16923 | M38: 16923 | N38: =SUM(B38:M38)
A39: ZARZĄDZANIE | B39: 56325.95 | C39: 56325.95 | D39: 56325.95 | E39: 56325.95 | F39: 56325.95 | G39: 56325.95 | H39: 56325.95 | I39: 56325.95 | J39: 56325.95 | K39: 56325.95 | L39: 56325.95 | M39: 56325.95 | N39: =SUM(B39:M39)
A40: DORADZTWO | B40: 5845 | C40: 5845 | D40: 5845 | E40: 5845 | F40: 5845 | G40: 5845 | H40: 5845 | I40: 5845 | J40: 5845 | K40: 5845 | L40: 5845 | M40: 5845 | N40: =SUM(B40:M40)
A41: INNY_1 | B41: 10930.2 | C41: 10930.2 | D41: 10930.2 | E41: 10930.2 | F41: 10930.2 | G41: 10930.2 | H41: 10930.2 | I41: 10930.2 | J41: 10930.2 | K41: 10930.2 | L41: 10930.2 | M41: 10930.2 | N41: =SUM(B41:M41)
A42: INNY_2 | B42: 0 | C42: 0 | D42: 0 | E42: 0 | F42: 0 | G42: 0 | H42: 0 | I42: 0 | J42: 0 | K42: 0 | L42: 0 | M42: 0 | N42: =SUM(B42:M42)
A43: INNY_3 | B43: 0 | C43: 0 | D43: 0 | E43: 0 | F43: 0 | G43: 0 | H43: 0 | I43: 0 | J43: 0 | K43: 0 | L43: 0 | M43: 0 | N43: =SUM(B43:M43)
A44: RAZEM DZIAŁY | B44: =SUM(B34:B43) | C44: =SUM(C34:C43) | D44: =SUM(D34:D43) | E44: =SUM(E34:E43) | F44: =SUM(F34:F43) | G44: =SUM(G34:G43) | H44: =SUM(H34:H43) | I44: =SUM(I34:I43) | ... N44: =SUM(N34:N43)

Sheet SPRZEDAŻ 2026
A1: SPRZEDAŻ 2026 — PLAN I WYKONANIE
A3: HISTORIA SPRZEDAŻY
A4: Rok | B4: Sty | C4: Lut | D4: Mar | E4: Kwi | F4: Maj | G4: Cze | H4: Lip | I4: Sie | J4: Wrz | K4: Paź | L4: Lis | M4: Gru | N4: RAZEM | O4: DYNAMIKA r/r | P4: MARŻA | Q4: ZYSK | R4: ZAKUP
A5: 2021 | B5: 76748 | C5: 97200 | D5: 116720 | E5: 231579 | F5: 132611 | G5: 146733 | H5: 156973 | I5: 157337 | J5: 187834 | K5: 185438 | L5: 225276 | M5: 226584 | N5: =SUM(B5:M5)
A6: 2022 | B6: 158856 | C6: 179042 | D6: 225250 | E6: 224587 | F6: 266557 | G6: 274665 | H6: 252263 | I6: 295688 | J6: 298446 | K6: 337719 | L6: 378226 | M6: 410150 | N6: =SUM(B6:M6) | O6: =IF(N5=0,"",N6/N5)
A7: 2023 | B7: 329707 | C7: 358484 | D7: 394903 | E7: 343711 | F7: 386671 | G7: 412280 | H7: 365324 | I7: 368797 | J7: 404277 | K7: 441641 | L7: 417416 | M7: 484211 | N7: =SUM(B7:M7) | O7: =IF(N6=0,"",N7/N6)
A8: 2024 | B8: 401663 | C8: 428475 | D8: 431370 | E8: 471086 | F8: 447356 | G8: 443643 | H8: 453842 | I8: 457660 | J8: 495675 | K8: 515817 | L8: 417538 | M8: 500000 | N8: =SUM(B8:M8) | O8: =IF(N7=0,"",N8/N7)
A9: 2025 | B9: 503721 | C9: 516838 | D9: 515000 | E9: 520000 | F9: 416425 | G9: 420000 | H9: 420000 | I9: 417178 | J9: 442288 | K9: 415390 | L9: 500000 | M9: 450000 | N9: =SUM(B9:M9) | O9: =IF(N8=0,"",N9/N8)
A11: PLAN SPRZEDAŻY 2026
A12: Kategoria | B12: Sty | C12: Lut | D12: Mar | E12: Kwi | F12: Maj | G12: Cze | H12: Lip | I12: Sie | J12: Wrz | K12: Paź | L12: Lis | M12: Gru | N12: RAZEM
A13: PLAN OBROTU | B13: 450000 | C13: 450000 | D13: 480000 | E13: 500000 | F13: 480000 | G13: 480000 | H13: 480000 | I13: 480000 | J13: 500000 | K13: 520000 | L13: 520000 | M13: 520000 | N13: =SUM(B13:M13)
A14: WYKONANIE | B14: 0 | C14: 0 | D14: 0 | E14: 0 | F14: 0 | G14: 0 | H14: 0 | I14: 0 | J14: 0 | K14: 0 | L14: 0 | M14: 0 | N14: =SUM(B14:M14)
A15: RÓŻNICA (wyk. - plan) | B15: =B14-B13 | C15: =C14-C13 | D15: =D14-D13 | E15: =E14-E13 | F15: =F14-F13 | G15: =G14-G13 | H15: =H14-H13 | I15: =I14-I13 | ... N15: =N14-N13
A16: % REALIZACJI | B16: =IF(B13=0,"",B14/B13) | C16: =IF(C13=0,"",C14/C13) | D16: =IF(D13=0,"",D14/D13) | E16: =IF(E13=0,"",E14/E13) | F16: =IF(F13=0,"",F14/F13) | G16: =IF(G13=0,"",G14/G13) | H16: =IF(H13=0,"",H14/H13) | I16: =IF(I13=0,"",I14/I13) | ... N16: =IF(N13=0,"",N14/N13)
A18: OBRÓT PLAN (narastająco) | B18: =B13 | C18: =B18+C13 | D18: =C18+D13 | E18: =D18+E13 | F18: =E18+F13 | G18: =F18+G13 | H18: =G18+H13 | I18: =H18+I13 | J18: =I18+J13 | ... M18: =L18+M13
A19: OBRÓT WYKONANIE (narastająco) | B19: =B14 | C19: =B19+C14 | D19: =C19+D14 | E19: =D19+E14 | F19: =E19+F14 | G19: =F19+G14 | H19: =G19+H14 | I19: =H19+I14 | J19: =I19+J14 | ... M19: =L19+M14
A21: ZAŁOŻENIA
A22: Marża sprzedaży | B22: 0.354
A24: HANDLOWCY
A25: Handlowiec | B25: Udział % | C25: Komentarz
A26: SKALO | B26: 0
A27: Handlowiec 1 - Gosia | B27: 0
A28: Handlowiec 2 - Anita | B28: 0.66
A29: Handlowiec 3 - Magda | B29: 0.34
A30: Handlowiec 4 | B30: 0
A32: SYSTEM PROWIZYJNY
A33: Osoba | B33: Stawka % | C33: Komentarz
A34: Dyrektor | B34: 0
A35: SKALO | B35: 0
A36: Handlowiec 1 | B36: 0
A37: Handlowiec 2 | B37: 0.0015
A38: Handlowiec 3 | B38: 0.0015
A39: Handlowiec 4 | B39: 0

Sheet WYNAGRODZENIA 2026
A1: WYNAGRODZENIA 2026 — ADD ALL SP. Z O.O.
A2: WYNAGRODZENIA ADDALL SP. Z O.O. — TOTAL | J2: =SUMPRODUCT(($J4:$J15="TAK")*($I4:$I15)) | K2: =SUMPRODUCT(($K4:$K15="TAK")*($I4:$I15)) | L2: =SUMPRODUCT(($L4:$L15="TAK")*($I4:$I15)) | M2: =SUMPRODUCT(($M4:$M15="TAK")*($I4:$I15)) | N2: =SUMPRODUCT(($N4:$N15="TAK")*($I4:$I15)) | O2: =SUMPRODUCT(($O4:$O15="TAK")*($I4:$I15)) | P2: =SUMPRODUCT(($P4:$P15="TAK")*($I4:$I15)) | Q2: =SUMPRODUCT(($Q4:$Q15="TAK")*($I4:$I15)) | R2: =SUMPRODUCT(($R4:$R15="TAK")*($I4:$I15)) | S2: =SUMPRODUCT(($S4:$S15="TAK")*($I4:$I15)) | T2: =SUMPRODUCT(($T4:$T15="TAK")*($I4:$I15)) | U2: =SUMPRODUCT(($U4:$U15="TAK")*($I4:$I15))
A3: Lp. | B3: OPIS | C3: FIRMA | D3: DZIAŁ | E3: FORMA ZATRUDNIENIA | F3: NETTO | G3: BRUTTO | H3: VAT | I3: KOSZT PRACODAWCY | J3: Sty | K3: Lut | L3: Mar | M3: Kwi | N3: Maj | O3: Cze | P3: Lip | Q3: Sie | R3: Wrz | S3: Paź | T3: Lis | U3: Gru
A4: 1 | B4: Małgorzata Rojek | C4: Add All Sp. z o.o. | D4: SPRZEDAŻ | E4: UoP | F4: 8000 | I4: 14500 | J4: TAK | K4: TAK | L4: TAK | M4: TAK | N4: TAK | O4: TAK | P4: TAK | Q4: TAK | R4: TAK | S4: TAK | T4: TAK | U4: TAK
A5: 2 | B5: Piotr Radzyński | C5: Add All Sp. z o.o. | D5: LOGISTYKA | E5: UoP | F5: 6000 | I5: 10400 | J5: TAK | K5: TAK | L5: TAK | M5: TAK | N5: TAK | O5: TAK | P5: TAK | Q5: TAK | R5: TAK | S5: TAK | T5: TAK | U5: TAK
A6: 3 | B6: Paulina Zielińska | C6: Add All Sp. z o.o. | D6: OPERACJE | E6: UoP | F6: 4300 | G6: 6002 | I6: 5654 | J6: TAK | K6: TAK | L6: TAK | M6: TAK | N6: TAK | O6: TAK | P6: TAK | Q6: TAK | R6: TAK | S6: TAK | T6: TAK | U6: TAK
A7: 4 | B7: Firma zewnętrzna | C7: Add All Sp. z o.o. | D7: LOGISTYKA | E7: FV | F7: 7800 | G7: 6116.61 | I7: 7800 | J7: TAK | K7: TAK | L7: TAK | M7: TAK | N7: TAK | O7: TAK | P7: TAK | Q7: TAK | R7: TAK | S7: TAK | T7: TAK | U7: TAK
A8: 5 | B8: Magdalena Grzelak | C8: Add All Sp. z o.o. | D8: SPRZEDAŻ | E8: UoP | F8: 5000 | G8: 6850 | I8: 8400 | J8: TAK | K8: TAK | L8: TAK | M8: TAK | N8: TAK | O8: TAK | P8: TAK | Q8: TAK | R8: TAK | S8: TAK | T8: TAK | U8: TAK
A9: 6 | B9: Agnieszka Dąbrowska | C9: Add All Sp. z o.o. | D9: ZARZĄDZANIE | E9: FV | F9: 13000 | H9: 2990 | I9: 13000 | J9: Nie | K9: Nie | L9: Nie | M9: Nie | N9: Nie | O9: Nie | P9: Nie | Q9: Nie | R9: Nie | S9: Nie | T9: Nie | U9: Nie
A10: 7 | B10: Dysponowanie pracownikami JDG | C10: Add All Sp. z o.o. | D10: ZARZĄDZANIE | E10: FV | F10: 21000 | I10: 22674.54 | J10: TAK | K10: TAK | L10: TAK | M10: TAK | N10: TAK | O10: TAK | P10: TAK | Q10: TAK | R10: TAK | S10: TAK | T10: TAK | U10: TAK
A11: 8 | B11: Zarząd p. Ania i p. Adam | C11: Add All Sp. z o.o. | D11: ZARZĄDZANIE | E11: FV | F11: 11000 | I11: 7400 | J11: TAK | K11: TAK | L11: TAK | M11: TAK | N11: TAK | O11: TAK | P11: TAK | Q11: TAK | R11: TAK | S11: TAK | T11: TAK | U11: TAK
A12: 9 | B12: Czeki nowe | C12: Add All Sp. z o.o. | D12: SPRZEDAŻ | I12: 8640 | J12: TAK | K12: TAK | L12: TAK | M12: TAK | N12: TAK | O12: TAK | P12: TAK | Q12: TAK | R12: TAK | S12: TAK | T12: TAK | U12: TAK
A13: 10 | B13: Rezerwa na wzrost wynagrodzeń | C13: Add All Sp. z o.o. | D13: ZARZĄDZANIE | E13: 5% | F13: 5000 | I13: 6485 | J13: NIE | K13: NIE | L13: NIE | M13: NIE | N13: NIE | O13: NIE | P13: NIE | Q13: NIE | R13: NIE | S13: NIE | T13: NIE | U13: NIE
A14: 11 | C14: Add All Sp. z o.o. | J14: NIE | K14: NIE | L14: NIE | M14: NIE | N14: NIE | O14: NIE | P14: NIE | Q14: NIE | R14: NIE | S14: NIE | T14: NIE | U14: NIE
A15: 12 | C15: Add All Sp. z o.o. | J15: NIE | K15: NIE | L15: NIE | M15: NIE | N15: NIE | O15: NIE | P15: NIE | Q15: NIE | R15: NIE | S15: NIE | T15: NIE | U15: NIE
A17: WYNAGRODZENIA ADDALL JDG
A18: Lp. | B18: OPIS | C18: FIRMA | D18: DZIAŁ | E18: FORMA ZATRUDNIENIA | F18: NETTO | G18: BRUTTO | H18: VAT | I18: KOSZT PRACODAWCY | J18: Sty | K18: Lut | L18: Mar | M18: Kwi | N18: Maj | O18: Cze | P18: Lip | Q18: Sie | R18: Wrz | S18: Paź | T18: Lis | U18: Gru
A19: 1 | B19: Anita Skłodowska | C19: Add All JDG | E19: UoP | F19: 3511 | G19: 4666 | I19: 5621.59
A20: 2 | B20: Mariusz Rosa | C20: Add All JDG
A21: 3 | B21: Dominik Żmudzki | C21: Add All JDG | E21: UoP | F21: 3511 | G21: 4666 | I21: 5621.59
A22: 4 | B22: Marek Zieliński | C22: Add All JDG | E22: UoP | F22: 3511 | G22: 4666 | I22: 5621.59
A23: 5 | B23: Teresa Kochman | C23: Add All JDG | E23: UoP | F23: 4000 | G23: 2547 | H23: 6640 | I23: 3320
A24: 6 | C24: Add All JDG
A25: 7 | C25: Add All JDG
A26: 8 | C26: Add All JDG
A28: PODSUMOWANIE WYNAGRODZEŃ WG DZIAŁÓW
D29: DZIAŁ | J29: Sty | K29: Lut | L29: Mar | M29: Kwi | N29: Maj | O29: Cze | P29: Lip | Q29: Sie | R29: Wrz | S29: Paź | T29: Lis | U29: Gru
D30: SPRZEDAŻ | J30: 0 | K30: 0 | L30: 0 | M30: 0 | N30: 0 | O30: 0 | P30: 0 | Q30: 0 | R30: 0 | S30: 0 | T30: 0 | U30: 0
D31: LOGISTYKA | J31: 0 | K31: 0 | L31: 0 | M31: 0 | N31: 0 | O31: 0 | P31: 0 | Q31: 0 | R31: 0 | S31: 0 | T31: 0 | U31: 0
D32: OPERACJE | J32: 0 | K32: 0 | L32: 0 | M32: 0 | N32: 0 | O32: 0 | P32: 0 | Q32: 0 | R32: 0 | S32: 0 | T32: 0 | U32: 0
D33: MAGAZYN | J33: 0 | K33: 0 | L33: 0 | M33: 0 | N33: 0 | O33: 0 | P33: 0 | Q33: 0 | R33: 0 | S33: 0 | T33: 0 | U33: 0
D34: ZARZĄDZANIE | J34: 0 | K34: 0 | L34: 0 | M34: 0 | N34: 0 | O34: 0 | P34: 0 | Q34: 0 | R34: 0 | S34: 0 | T34: 0 | U34: 0
D35: DORADZTWO | J35: 0 | K35: 0 | L35: 0 | M35: 0 | N35: 0 | O35: 0 | P35: 0 | Q35: 0 | R35: 0 | S35: 0 | T35: 0 | U35: 0

Sheet OPERACYJNE 2026
A1: KOSZTY OPERACYJNE 2026 — ADD ALL SP. Z O.O.
A2: OPERACYJNE ADDALL SP. Z O.O. — TOTAL | J2: =SUMPRODUCT(($J4:$J26="TAK")*($I4:$I26)) | K2: =SUMPRODUCT(($K4:$K26="TAK")*($I4:$I26)) | L2: =SUMPRODUCT(($L4:$L26="TAK")*($I4:$I26)) | M2: =SUMPRODUCT(($M4:$M26="TAK")*($I4:$I26)) | N2: =SUMPRODUCT(($N4:$N26="TAK")*($I4:$I26)) | O2: =SUMPRODUCT(($O4:$O26="TAK")*($I4:$I26)) | P2: =SUMPRODUCT(($P4:$P26="TAK")*($I4:$I26)) | Q2: =SUMPRODUCT(($Q4:$Q26="TAK")*($I4:$I26)) | R2: =SUMPRODUCT(($R4:$R26="TAK")*($I4:$I26)) | S2: =SUMPRODUCT(($S4:$S26="TAK")*($I4:$I26)) | T2: =SUMPRODUCT(($T4:$T26="TAK")*($I4:$I26)) | U2: =SUMPRODUCT(($U4:$U26="TAK")*($I4:$I26))
A3: Lp. | B3: OPIS | C3: FIRMA | D3: DZIAŁ | E3: KOMENTARZ | F3: NETTO | G3: BRUTTO | H3: VAT | I3: KOSZT | J3: Sty | K3: Lut | L3: Mar | M3: Kwi | N3: Maj | O3: Cze | P3: Lip | Q3: Sie | R3: Wrz | S3: Paź | T3: Lis | U3: Gru
A4: 1 | B4: Magazyn (najem) | C4: Add All Sp. z o.o. | D4: MAGAZYN | F4: 6000 | I4: 10000 | J4: TAK | K4: TAK | L4: TAK | M4: TAK | N4: TAK | O4: TAK | P4: TAK | Q4: TAK | R4: TAK | S4: TAK | T4: TAK | U4: TAK
A5: 2 | B5: Księgowość | C5: Add All Sp. z o.o. | D5: DORADZTWO | F5: 5500 | I5: 5845 | J5: TAK | K5: TAK | L5: TAK | M5: TAK | N5: TAK | O5: TAK | P5: TAK | Q5: TAK | R5: TAK | S5: TAK | T5: TAK | U5: TAK
A6: 3 | B6: Artykuły biurowe | C6: Add All Sp. z o.o. | D6: INNY_1 | F6: 500 | I6: 380 | J6: TAK | K6: TAK | L6: TAK | M6: TAK | N6: TAK | O6: TAK | P6: TAK | Q6: TAK | R6: TAK | S6: TAK | T6: TAK | U6: TAK
A7: 4 | B7: Artykuły spożywcze | C7: Add All Sp. z o.o. | D7: INNY_1 | F7: 500 | I7: 550 | J7: TAK | K7: TAK | L7: TAK | M7: TAK | N7: TAK | O7: TAK | P7: TAK | Q7: TAK | R7: TAK | S7: TAK | T7: TAK | U7: TAK
A8: 5 | B8: Artykuły budowlane / wyposażenie | C8: Add All Sp. z o.o. | D8: INNY_1 | F8: 1600 | I8: 5 | J8: TAK | K8: TAK | L8: TAK | M8: TAK | N8: TAK | O8: TAK | P8: TAK | Q8: TAK | R8: TAK | S8: TAK | T8: TAK | U8: TAK
A9: 6 | B9: Media (Prąd, woda, śmieci) | C9: Add All Sp. z o.o. | D9: ZARZĄDZANIE | F9: 2800 | I9: 1301 | J9: TAK | K9: TAK | L9: TAK | M9: TAK | N9: TAK | O9: TAK | P9: TAK | Q9: TAK | R9: TAK | S9: TAK | T9: TAK | U9: TAK
A10: 7 | B10: Paliwo | C10: Add All Sp. z o.o. | D10: LOGISTYKA | F10: 5700 | I10: 5000 | J10: TAK | K10: TAK | L10: TAK | M10: TAK | N10: TAK | O10: TAK | P10: TAK | Q10: TAK | R10: TAK | S10: TAK | T10: TAK | U10: TAK
A11: 8 | B11: Marketing | C11: Add All Sp. z o.o. | D11: SPRZEDAŻ | F11: 650 | I11: 470 | J11: TAK | K11: TAK | L11: TAK | M11: TAK | N11: TAK | O11: TAK | P11: TAK | Q11: TAK | R11: TAK | S11: TAK | T11: TAK | U11: TAK
A12: 9 | B12: Usługi telekomunikacyjne | C12: Add All Sp. z o.o. | D12: ZARZĄDZANIE | F12: 600 | I12: 600 | J12: NIE | K12: NIE | L12: NIE | M12: NIE | N12: NIE | O12: NIE | P12: NIE | Q12: NIE | R12: NIE | S12: NIE | T12: NIE | U12: NIE
A13: 10 | B13: Budżet handlowy | C13: Add All Sp. z o.o. | D13: SPRZEDAŻ | E13: parkingi | F13: 100 | I13: 100 | J13: TAK | K13: TAK | L13: TAK | M13: TAK | N13: TAK | O13: TAK | P13: TAK | Q13: TAK | R13: TAK | S13: TAK | T13: TAK | U13: TAK
A14: 11 | B14: Budżet na prezenty (klienci-święta) | C14: Add All Sp. z o.o. | D14: SPRZEDAŻ | F14: 10500 | I14: 6000 | J14: NIE | K14: NIE | L14: NIE | M14: NIE | N14: NIE | O14: NIE | P14: NIE | Q14: NIE | R14: NIE | S14: NIE | T14: TAK | U14: NIE
A15: 12 | B15: Budżet na prezenty (pracownicy) | C15: Add All Sp. z o.o. | D15: INNY_1 | F15: 10000 | I15: 10000 | J15: NIE | K15: NIE | L15: NIE | M15: NIE | N15: NIE | O15: NIE | P15: NIE | Q15: NIE | R15: NIE | S15: NIE | T15: NIE | U15: TAK
A16: 13 | B16: Wigilia | C16: Add All Sp. z o.o. | D16: INNY_1 | F16: 5500 | I16: 5500 | J16: NIE | K16: NIE | L16: NIE | M16: NIE | N16: NIE | O16: NIE | P16: NIE | Q16: NIE | R16: NIE | S16: NIE | T16: NIE | U16: TAK
A17: 14 | B17: Dodatkowe (transport, poczta) | C17: Add All Sp. z o.o. | D17: INNY_1 | F17: 600 | I17: 940 | J17: TAK | K17: TAK | L17: TAK | M17: TAK | N17: TAK | O17: TAK | P17: TAK | Q17: TAK | R17: TAK | S17: TAK | T17: TAK | U17: TAK
A18: 15 | B18: Naprawy, przeglądy | C18: Add All Sp. z o.o. | D18: LOGISTYKA | F18: 2500 | I18: 1700 | J18: TAK | K18: TAK | L18: TAK | M18: TAK | N18: TAK | O18: TAK | P18: TAK | Q18: TAK | R18: TAK | S18: TAK | T18: TAK | U18: TAK
A19: 16 | B19: Ubezpieczenia samochodów | C19: Add All Sp. z o.o. | D19: LOGISTYKA | F19: 1800 | I19: 4658 | J19: NIE | K19: NIE | L19: NIE | M19: NIE | N19: NIE | O19: NIE | P19: NIE | Q19: NIE | R19: NIE | S19: NIE | T19: NIE | U19: NIE
A20: 17 | B20: Fundusz nieprzewidziany | C20: Add All Sp. z o.o. | D20: ZARZĄDZANIE | F20: 700 | I20: 700 | J20: TAK | K20: TAK | L20: TAK | M20: TAK | N20: TAK | O20: TAK | P20: TAK | Q20: TAK | R20: TAK | S20: TAK | T20: TAK | U20: TAK
A21: 18 | B21: Finansowanie | C21: Add All Sp. z o.o. | D21: DORADZTWO | F21: 1250 | I21: 1824 | J21: TAK | K21: TAK | L21: TAK | M21: TAK | N21: TAK | O21: TAK | P21: TAK | Q21: TAK | R21: TAK | S21: TAK | T21: TAK | U21: TAK
A22: 19 | B22: Zarządzanie Operacyjne od JDG | C22: Add All Sp. z o.o. | D22: ZARZĄDZANIE | F22: 5000 | I22: 5000 | J22: TAK | K22: TAK | L22: TAK | M22: TAK | N22: TAK | O22: TAK | P22: TAK | Q22: TAK | R22: TAK | S22: TAK | T22: TAK | U22: TAK
A23: 20 | B23: Szkolenia | C23: Add All Sp. z o.o. | D23: INNY_1 | F23: 650 | I23: 2900 | J23: NIE | K23: NIE | L23: NIE | M23: NIE | N23: NIE | O23: NIE | P23: NIE | Q23: NIE | R23: NIE | S23: NIE | T23: NIE | U23: NIE
A24: 21 | B24: Integracja | C24: Add All Sp. z o.o. | D24: INNY_1 | F24: 350 | I24: 317 | J24: NIE | K24: NIE | L24: NIE | M24: NIE | N24: NIE | O24: NIE | P24: NIE | Q24: NIE | R24: NIE | S24: NIE | T24: NIE | U24: NIE
A25: 22 | C25: Add All Sp. z o.o. | J25: NIE | K25: NIE | L25: NIE | M25: NIE | N25: NIE | O25: NIE | P25: NIE | Q25: NIE | R25: NIE | S25: NIE | T25: NIE | U25: NIE
A26: 23 | C26: Add All Sp. z o.o. | J26: NIE | K26: NIE | L26: NIE | M26: NIE | N26: NIE | O26: NIE | P26: NIE | Q26: NIE | R26: NIE | S26: NIE | T26: NIE | U26: NIE

Sheet SAMOCHODY 2026
A1: SAMOCHODY I FLOTA 2026
A2: SAMOCHODY ADDALL SP. Z O.O. — TOTAL | J2: =SUMPRODUCT(($J4:$J13="TAK")*($I4:$I13)) | K2: =SUMPRODUCT(($K4:$K13="TAK")*($I4:$I13)) | L2: =SUMPRODUCT(($L4:$L13="TAK")*($I4:$I13)) | M2: =SUMPRODUCT(($M4:$M13="TAK")*($I4:$I13)) | N2: =SUMPRODUCT(($N4:$N13="TAK")*($I4:$I13)) | O2: =SUMPRODUCT(($O4:$O13="TAK")*($I4:$I13)) | P2: =SUMPRODUCT(($P4:$P13="TAK")*($I4:$I13)) | Q2: =SUMPRODUCT(($Q4:$Q13="TAK")*($I4:$I13)) | R2: =SUMPRODUCT(($R4:$R13="TAK")*($I4:$I13)) | S2: =SUMPRODUCT(($S4:$S13="TAK")*($I4:$I13)) | T2: =SUMPRODUCT(($T4:$T13="TAK")*($I4:$I13)) | U2: =SUMPRODUCT(($U4:$U13="TAK")*($I4:$I13))
A3: Lp. | B3: OPIS | C3: FIRMA | D3: DZIAŁ | E3: RODZAJ | F3: NETTO | G3: BRUTTO | H3: VAT | I3: KOSZT | J3: Sty | K3: Lut | L3: Mar | M3: Kwi | N3: Maj | O3: Cze | P3: Lip | Q3: Sie | R3: Wrz | S3: Paź | T3: Lis | U3: Gru
A4: 1 | B4: Dzierżawa z AddAll JDG | C4: Add All Sp. z o.o. | D4: LOGISTYKA | E4: Dzierżawa | F4: 7000 | I4: 3900 | J4: TAK | K4: TAK | L4: TAK | M4: TAK | N4: TAK | O4: TAK | P4: TAK | Q4: TAK | R4: TAK | S4: TAK | T4: TAK | U4: TAK
A5: 2 | B5: Opel Movano WU2520S LEASING | C5: Add All Sp. z o.o. | D5: LOGISTYKA | E5: Leasing | F5: 2498 | I5: 2475 | J5: TAK | K5: TAK | L5: TAK | M5: TAK | N5: TAK | O5: TAK | P5: TAK | Q5: TAK | R5: TAK | S5: TAK | T5: TAK | U5: TAK
A6: 3 | B6: Ford Custom leasing | C6: Add All Sp. z o.o. | D6: LOGISTYKA | E6: Leasing | F6: 1706 | I6: 1687 | J6: TAK | K6: TAK | L6: TAK | M6: TAK | N6: TAK | O6: TAK | P6: TAK | Q6: TAK | R6: TAK | S6: TAK | T6: TAK | U6: TAK
A7: 4 | B7: 2xBMW 3 rata leasingowa | C7: Add All Sp. z o.o. | D7: LOGISTYKA | E7: Leasing | I7: 3298 | J7: TAK | K7: TAK | L7: TAK | M7: TAK | N7: TAK | O7: TAK | P7: TAK | Q7: TAK | R7: TAK | S7: TAK | T7: TAK | U7: TAK
A8: 5 | B8: Widziszwszystko (GPS) | C8: Add All Sp. z o.o. | D8: LOGISTYKA | E8: Usługa | I8: 300 | J8: TAK | K8: TAK | L8: TAK | M8: TAK | N8: TAK | O8: TAK | P8: TAK | Q8: TAK | R8: TAK | S8: TAK | T8: TAK | U8: TAK
A9: 6 | B9: Paliwo (flota) | C9: Add All Sp. z o.o. | D9: LOGISTYKA | E9: Eksploat. | I9: 2714 | J9: TAK | K9: TAK | L9: TAK | M9: TAK | N9: TAK | O9: TAK | P9: TAK | Q9: TAK | R9: TAK | S9: TAK | T9: TAK | U9: TAK
A10: 7 | B10: Naprawy, przeglądy, opony | C10: Add All Sp. z o.o. | D10: LOGISTYKA | E10: Eksploat. | I10: 1204 | J10: TAK | K10: TAK | L10: TAK | M10: TAK | N10: TAK | O10: TAK | P10: TAK | Q10: TAK | R10: TAK | S10: TAK | T10: TAK | U10: TAK
A11: 8 | B11: Ubezpieczenia pojazdów | C11: Add All Sp. z o.o. | D11: LOGISTYKA | E11: Ubezp. | I11: 2760 | J11: NIE | K11: NIE | L11: NIE | M11: NIE | N11: NIE | O11: NIE | P11: NIE | Q11: NIE | R11: NIE | S11: NIE | T11: NIE | U11: NIE
A12: 9 | C12: Add All Sp. z o.o. | J12: NIE | K12: NIE | L12: NIE | M12: NIE | N12: NIE | O12: NIE | P12: NIE | Q12: NIE | R12: NIE | S12: NIE | T12: NIE | U12: NIE
A13: 10 | C13: Add All Sp. z o.o. | J13: NIE | K13: NIE | L13: NIE | M13: NIE | N13: NIE | O13: NIE | P13: NIE | Q13: NIE | R13: NIE | S13: NIE | T13: NIE | U13: NIE
A16: SAMOCHODY ADDALL JDG
A17: Lp. | B17: OPIS | C17: FIRMA | D17: DZIAŁ | E17: RODZAJ | F17: NETTO | G17: BRUTTO | H17: VAT | I17: KOSZT | J17: Sty | K17: Lut | L17: Mar | M17: Kwi | N17: Maj | O17: Cze | P17: Lip | Q17: Sie | R17: Wrz | S17: Paź | T17: Lis | U17: Gru
A18: 1 | B18: Peugeot Expert WBR 74V7 | C18: Add All JDG | E18: Ciężarowy | F18: 1000
A19: 2 | B19: Peugeot Expert WPI 89341 | C19: Add All JDG | E19: Ciężarowy | F19: 1000
A20: 3 | B20: BMW WPI4029F | C20: Add All JDG | E20: Osobowy | F20: 750
A21: 4 | B21: BMW WPI0679P | C21: Add All JDG | E21: Osobowy | F21: 1116.65
A22: 5 | B22: NISSAN JUKE | C22: Add All JDG | E22: Osobowy | F22: 750
A23: 6 | B23: Wózek widłowy Jungheinrich | C23: Add All JDG | E23: Wózek | F23: 1750
A24: 7 | B24: HARLEY DAVIDSON motocykl | C24: Add All JDG | E24: Motocykl | F24: 234.6
A25: 8 | C25: Add All JDG

Sheet WYKONANIE 2026
A1: WYKONANIE BUDŻETU 2026 — DANE RZECZYWISTE
A2: Uzupełniaj ten arkusz co miesiąc danymi rzeczywistymi
A4: Kategoria | B4: Sty | C4: Lut | D4: Mar | E4: Kwi | F4: Maj | G4: Cze | H4: Lip | I4: Sie | J4: Wrz | K4: Paź | L4: Lis | M4: Gru | N4: RAZEM
A5: PRZYCHODY RZECZYWISTE
A6: Sprzedaż produktów | N6: =SUM(B6:M6)
A7: Przychody zewnętrzne | N7: =SUM(B7:M7)
A8: Przychody wewnętrzne | N8: =SUM(B8:M8)
A9: PRZYCHODY OGÓŁEM (rzecz.) | B9: =SUM(B6:B8) | C9: =SUM(C6:C8) | D9: =SUM(D6:D8) | E9: =SUM(E6:E8) | F9: =SUM(F6:F8) | G9: =SUM(G6:G8) | H9: =SUM(H6:H8) | I9: =SUM(I6:I8) | ... M9: =SUM(M6:M8) | N9: =SUM(B9:M9)
A11: KOSZTY RZECZYWISTE
A12: Zakupy towarów | N12: =SUM(B12:M12)
A13: Prowizje | N13: =SUM(B13:M13)
A14: Wynagrodzenia | N14: =SUM(B14:M14)
A15: Koszty operacyjne | N15: =SUM(B15:M15)
A16: Samochody / Amortyzacja | N16: =SUM(B16:M16)
A17: KOSZTY OGÓŁEM (rzecz.) | B17: =SUM(B12:B16) | C17: =SUM(C12:C16) | D17: =SUM(D12:D16) | E17: =SUM(E12:E16) | F17: =SUM(F12:F16) | G17: =SUM(G12:G16) | H17: =SUM(H12:H16) | I17: =SUM(I12:I16) | ... M17: =SUM(M12:M16) | N17: =SUM(B17:M17)
A19: WYNIK RZECZYWISTY | B19: =B9-B17 | C19: =C9-C17 | D19: =D9-D17 | E19: =E9-E17 | F19: =F9-F17 | G19: =G9-G17 | H19: =H9-H17 | I19: =I9-I17 | ... M19: =M9-M17 | N19: =SUM(B19:M19)
A21: ODCHYLENIA: PLAN vs WYKONANIE
A22: Kategoria | B22: Sty | C22: Lut | D22: Mar | E22: Kwi | F22: Maj | G22: Cze | H22: Lip | I22: Sie | J22: Wrz | K22: Paź | L22: Lis | M22: Gru | N22: RAZEM
A23: Odchylenie przychodów | B23: =B9-'PROGNOZA 2026'!B9 | C23: =C9-'PROGNOZA 2026'!C9 | D23: =D9-'PROGNOZA 2026'!D9 | E23: =E9-'PROGNOZA 2026'!E9 | F23: =F9-'PROGNOZA 2026'!F9 | G23: =G9-'PROGNOZA 2026'!G9 | H23: =H9-'PROGNOZA 2026'!H9 | I23: =I9-'PROGNOZA 2026'!I9 | ... N23: =N9-'PROGNOZA 2026'!N9
A24: Odchylenie kosztów | B24: =B17-'PROGNOZA 2026'!B18 | C24: =C17-'PROGNOZA 2026'!C18 | D24: =D17-'PROGNOZA 2026'!D18 | E24: =E17-'PROGNOZA 2026'!E18 | F24: =F17-'PROGNOZA 2026'!F18 | G24: =G17-'PROGNOZA 2026'!G18 | H24: =H17-'PROGNOZA 2026'!H18 | I24: =I17-'PROGNOZA 2026'!I18 | ... N24: =N17-'PROGNOZA 2026'!N18
A25: Odchylenie wyniku | B25: =B19-'PROGNOZA 2026'!B20 | C25: =C19-'PROGNOZA 2026'!C20 | D25: =D19-'PROGNOZA 2026'!D20 | E25: =E19-'PROGNOZA 2026'!E20 | F25: =F19-'PROGNOZA 2026'!F20 | G25: =G19-'PROGNOZA 2026'!G20 | H25: =H19-'PROGNOZA 2026'!H20 | I25: =I19-'PROGNOZA 2026'!I20 | ... N25: =N19-'PROGNOZA 2026'!N20

Sheet CASH FLOW 2026
A1: PRZEPŁYWY PIENIĘŻNE 2026
A3: Pozycja | B3: Sty | C3: Lut | D3: Mar | E3: Kwi | F3: Maj | G3: Cze | H3: Lip | I3: Sie | J3: Wrz | K3: Paź | L3: Lis | M3: Gru | N3: RAZEM
A4: WPŁYWY
A5: Wpływy ze sprzedaży (gotówka) | N5: =SUM(B5:M5)
A6: Wpływy ze sprzedaży (przelewy) | N6: =SUM(B6:M6)
A7: Inne wpływy | N7: =SUM(B7:M7)
A8: Otrzymane pożyczki | N8: =SUM(B8:M8)
A9: WPŁYWY RAZEM | B9: =SUM(B5:B8) | C9: =SUM(C5:C8) | D9: =SUM(D5:D8) | E9: =SUM(E5:E8) | F9: =SUM(F5:F8) | G9: =SUM(G5:G8) | H9: =SUM(H5:H8) | I9: =SUM(I5:I8) | ... N9: =SUM(N5:N8)
A11: WYDATKI
A12: Zakupy towarów | N12: =SUM(B12:M12)
A13: Wynagrodzenia | N13: =SUM(B13:M13)
A14: ZUS/podatki | N14: =SUM(B14:M14)
A15: Koszty operacyjne | N15: =SUM(B15:M15)
A16: Leasing/raty | N16: =SUM(B16:M16)
A17: Paliwo | N17: =SUM(B17:M17)
A18: Spłata pożyczek | N18: =SUM(B18:M18)
A19: Inne wydatki | N19: =SUM(B19:M19)
A20: WYDATKI RAZEM | B20: =SUM(B12:B19) | C20: =SUM(C12:C19) | D20: =SUM(D12:D19) | E20: =SUM(E12:E19) | F20: =SUM(F12:F19) | G20: =SUM(G12:G19) | H20: =SUM(H12:H19) | I20: =SUM(I12:I19) | ... N20: =SUM(N12:N19)
A22: SALDO MIESIĘCZNE | B22: =B9-B20 | C22: =C9-C20 | D22: =D9-D20 | E22: =E9-E20 | F22: =F9-F20 | G22: =G9-G20 | H22: =H9-H20 | I22: =I9-I20 | ... N22: =N9-N20
A23: STAN GOTÓWKI (początek) | B23: 0 | C23: =B24 | D23: =C24 | E23: =D24 | F23: =E24 | G23: =F24 | H23: =G24 | I23: =H24 | J23: =I24 | ... M23: =L24
A24: STAN GOTÓWKI (koniec) | B24: =B23+B22 | C24: =C23+C22 | D24: =D23+D22 | E24: =E23+E22 | F24: =F23+F22 | G24: =G23+G22 | H24: =H23+H22 | I24: =I23+I22 | ... M24: =M23+M22

Sheet FAKTURY OD JDG
A1: FAKTURY OD JDG — UMOWY
A3: Lp. | B3: Umowa | C3: Koszt netto | D3: Kategoria | E3: Płatność
A4: 1 | B4: Umowa menadżerska - A. Rękawek | C4: 11850 | D4: Wynagrodzenia | E4: Przelew
A5: 2 | B5: Umowa dysponowania pracownikami | C5: 22674.54 | D5: Wynagrodzenia | E5: Przelew
A6: 3 | B6: Umowa zarządzania operacyjnego | C6: 5000 | D6: Operacyjny | E6: Gotówka
A7: 4 | B7: Umowa dzierżawy | C7: 3900 | D7: Samochody | E7: Gotówka
B8: RAZEM | C8: =SUM(C4:C7)

Sheet NOTATKI
A1: NOTATKI I ZAŁOŻENIA BUDŻETOWE
A3: Data | B3: Notatka / Założenie | C3: Autor
A4: 2026-02-08 | B4: Budżet przygotowany na podstawie danych z 2025 roku (przymiarki) | C4: System
A5: 2026-02-08 | B5: Marża sprzedaży założona na poziomie 35,4% | C5: System
A6: 2026-02-08 | B6: Dane wynagrodzeń bazują na aktualnej liście pracowników | C6: System
A7: 2026-02-08 | B7: Komórki żółte (WYKONANIE) do uzupełniania co miesiąc danymi rzeczywistymi | C7: System
A8: 2026-02-08 | B8: Komórki jasno-zielone (TAK) = koszt aktywny w danym miesiącu | C8: System
A9: 2026-02-08 | B9: Komórki jasno-czerwone (NIE) = koszt nieaktywny | C9: System
